Workbook
Name Slicer_Branch_ID: #N/A
Name Slicer_Customer_Ranking: #N/A
Name Slicer_Membership_Type: #N/A

Sheet Name pool
A1: First_Name | B1: Last_Name
A2: Rahul | B2: Nair
A3: Arjun | B3: Menon
A4: Vivek | B4: Pillai
A5: Rohit | B5: Nambiar
A6: Aditya | B6: Iyer
A7: Karthik | B7: Reddy
A8: Siddharth | B8: Sharma
A9: Nikhil | B9: Gupta
A10: Manoj | B10: Agarwal
A11: Akash | B11: Singh
A12: Varun | B12: Yadav
... A35: Tanvi | B35: Lewis

Sheet Branch_Master
A1: A (Branch ID) | B1: B (City)
A2: BR01 | B2: Kochi
A3: BR02 | B3: Bangalore
A4: BR03 | B4: Chennai
A5: BR04 | B5: Hyderabad
A6: BR05 | B6: Mumbai
A7: BR06 | B7: Trivandrum
A8: BR07 | B8: Calicut

Sheet Raw_Data
A1: Member ID | B1: Member Name | C1: City | D1: Branch ID | E1: Membership Type | F1: Join Date | G1: Expiry Date | H1: Monthly Fee | I1: Total Payments | J1: Attendance | K1: Trainer Assigned | L1: Workout Goal | M1: Status | N1: Last Visit Date | Q1: City name messy | R1: Attendance messy | S1: Monthly fee messy | T1: Join date Messy | U1: Last visit date Messy
A2: ="MEM" & TEXT(ROW()-1,"0000") -> MEM0001 | B2: =INDEX('Name pool'!A:A, RANDBETWEEN(2, COUNTA('Name pool'!A:A))) & " " & INDEX('Name pool'!B:B, RANDBETWEEN(2, COUNTA('Name pool'!B:B))) -> Karthik Joshi | C2: Chennai | D2: =CHOOSE(RANDBETWEEN(1,7),"BR01","BR02","BR03","BR04","BR05","BR06","BR07") -> BR07 | E2: =CHOOSE(RANDBETWEEN(1,3),"Basic","Standard","Premium") -> Premium | F2: 45630 | G2: 45660 | H2: 1000 | I2: =H2 * RANDBETWEEN(1,12) -> 8000 | J2: 18 | K2: =CHOOSE(RANDBETWEEN(1,2),"Yes","No") -> No | L2: =CHOOSE(RANDBETWEEN(1,3),"Weight Loss","Muscle Gain","General Fitness") -> Weight Loss | M2: =IF(J2<5,IF(RANDBETWEEN(1,100)<70,"Cancelled","Active"),"Active") -> Active | N2: 46022 | Q2: =IF(RAND()<0.2, IF(RAND()<0.5, LOWER(C2), UPPER(C2)), C2 ) -> Chennai | R2: =IF(RAND()<0.15, J2 & " visits", J2 ) -> 18 | S2: =IF(RAND()<0.1, TEXT(H2,"0"), H2 ) -> 1000 | T2: =IF(F2="", DATE(2023,1,1)+RANDBETWEEN(0,900), F2) -> 45630 | U2: =IF( M2="Cancelled", F2 + RANDBETWEEN(5, DATEDIF(F2, G2, "D")), F2 + RANDBETWEEN(5, DATEDIF(F2, TODAY(), "D")) ) -> 46110
A3: ="MEM" & TEXT(ROW()-1,"0000") -> MEM0002 | B3: =INDEX('Name pool'!A:A, RANDBETWEEN(2, COUNTA('Name pool'!A:A))) & " " & INDEX('Name pool'!B:B, RANDBETWEEN(2, COUNTA('Name pool'!B:B))) -> Meera George | C3: Mumbai | D3: =CHOOSE(RANDBETWEEN(1,7),"BR01","BR02","BR03","BR04","BR05","BR06","BR07") -> BR01 | E3: =CHOOSE(RANDBETWEEN(1,3),"Basic","Standard","Premium") -> Basic | F3: 45446 | G3: 45536 | H3: 3500 | I3: =H3 * RANDBETWEEN(1,12) -> 17500 | J3: 0 visits | K3: =CHOOSE(RANDBETWEEN(1,2),"Yes","No") -> No | L3: =CHOOSE(RANDBETWEEN(1,3),"Weight Loss","Muscle Gain","General Fitness") -> Muscle Gain | M3: =IF(J3<5,IF(RANDBETWEEN(1,100)<70,"Cancelled","Active"),"Active") -> Active | N3: 46050 | Q3: =IF(RAND()<0.2, IF(RAND()<0.5, LOWER(C3), UPPER(C3)), C3 ) -> mumbai | R3: =IF(RAND()<0.15, J3 & " visits", J3 ) -> 0 visits visits | S3: =IF(RAND()<0.1, TEXT(H3,"0"), H3 ) -> 3500 | T3: =RANDBETWEEN(DATE(2023,1,1), DATE(2026,1,31)) -> 45233 | U3: =IF(AND(M3="Cancelled", RAND()<0.5), F3 + RANDBETWEEN(10,50), N3 ) -> 46050
A4: ="MEM" & TEXT(ROW()-1,"0000") -> MEM0003 | B4: =INDEX('Name pool'!A:A, RANDBETWEEN(2, COUNTA('Name pool'!A:A))) & " " & INDEX('Name pool'!B:B, RANDBETWEEN(2, COUNTA('Name pool'!B:B))) -> Fatima Das | C4: TRIVANDRUM | D4: =CHOOSE(RANDBETWEEN(1,7),"BR01","BR02","BR03","BR04","BR05","BR06","BR07") -> BR05 | E4: =CHOOSE(RANDBETWEEN(1,3),"Basic","Standard","Premium") -> Premium | F4: 44945 | G4: 45035 | H4: 3500 | I4: =H4 * RANDBETWEEN(1,12) -> 42000 | J4: 1 | K4: =CHOOSE(RANDBETWEEN(1,2),"Yes","No") -> No | L4: =CHOOSE(RANDBETWEEN(1,3),"Weight Loss","Muscle Gain","General Fitness") -> Weight Loss | M4: =IF(J4<5,IF(RANDBETWEEN(1,100)<70,"Cancelled","Active"),"Active") -> Active | N4: 45257 | Q4: =IF(RAND()<0.2, IF(RAND()<0.5, LOWER(C4), UPPER(C4)), C4 ) -> TRIVANDRUM | R4: =IF(RAND()<0.15, J4 & " visits", J4 ) -> 1 | S4: =IF(RAND()<0.1, TEXT(H4,"0"), H4 ) -> 3500 | T4: =RANDBETWEEN(DATE(2023,1,1), DATE(2026,1,31)) -> 45357 | U4: =IF(AND(M4="Cancelled", RAND()<0.5), F4 + RANDBETWEEN(10,50), N4 ) -> 45257
A5: ="MEM" & TEXT(ROW()-1,"0000") -> MEM0004 | B5: =INDEX('Name pool'!A:A, RANDBETWEEN(2, COUNTA('Name pool'!A:A))) & " " & INDEX('Name pool'!B:B, RANDBETWEEN(2, COUNTA('Name pool'!B:B))) -> Priya D’Souza | C5: Kochi | D5: =CHOOSE(RANDBETWEEN(1,7),"BR01","BR02","BR03","BR04","BR05","BR06","BR07") -> BR04 | E5: =CHOOSE(RANDBETWEEN(1,3),"Basic","Standard","Premium") -> Premium | F5: 45342 | G5: 45432 | H5: 3500 | I5: =H5 * RANDBETWEEN(1,12) -> 14000 | J5: 13 | K5: =CHOOSE(RANDBETWEEN(1,2),"Yes","No") -> Yes | L5: =CHOOSE(RANDBETWEEN(1,3),"Weight Loss","Muscle Gain","General Fitness") -> Weight Loss | M5: =IF(J5<5,IF(RANDBETWEEN(1,100)<70,"Cancelled","Active"),"Active") -> Active | N5: 45937 | Q5: =IF(RAND()<0.2, IF(RAND()<0.5, LOWER(C5), UPPER(C5)), C5 ) -> Kochi | R5: =IF(RAND()<0.15, J5 & " visits", J5 ) -> 13 | S5: =IF(RAND()<0.1, TEXT(H5,"0"), H5 ) -> 3500 | T5: =RANDBETWEEN(DATE(2023,1,1), DATE(2026,1,31)) -> 45581 | U5: =IF(AND(M5="Cancelled", RAND()<0.5), F5 + RANDBETWEEN(10,50), N5 ) -> 45937
A6: ="MEM" & TEXT(ROW()-1,"0000") -> MEM0005 | B6: =INDEX('Name pool'!A:A, RANDBETWEEN(2, COUNTA('Name pool'!A:A))) & " " & INDEX('Name pool'!B:B, RANDBETWEEN(2, COUNTA('Name pool'!B:B))) -> Sanjay Patel | C6: Mumbai | D6: =CHOOSE(RANDBETWEEN(1,7),"BR01","BR02","BR03","BR04","BR05","BR06","BR07") -> BR04 | E6: =CHOOSE(RANDBETWEEN(1,3),"Basic","Standard","Premium") -> Standard | F6: 45891 | G6: 46256 | H6: 1000 | I6: =H6 * RANDBETWEEN(1,12) -> 6000 | J6: 20 | K6: =CHOOSE(RANDBETWEEN(1,2),"Yes","No") -> No | L6: =CHOOSE(RANDBETWEEN(1,3),"Weight Loss","Muscle Gain","General Fitness") -> Weight Loss | M6: =IF(J6<5,IF(RANDBETWEEN(1,100)<70,"Cancelled","Active"),"Active") -> Active | N6: 45960 | Q6: =IF(RAND()<0.2, IF(RAND()<0.5, LOWER(C6), UPPER(C6)), C6 ) -> Mumbai | R6: =IF(RAND()<0.15, J6 & " visits", J6 ) -> 20 | S6: =IF(RAND()<0.1, TEXT(H6,"0"), H6 ) -> 1000 | T6: =RANDBETWEEN(DATE(2023,1,1), DATE(2026,1,31)) -> 44929 | U6: =IF(AND(M6="Cancelled", RAND()<0.5), F6 + RANDBETWEEN(10,50), N6 ) -> 45960
A7: ="MEM" & TEXT(ROW()-1,"0000") -> MEM0006 | B7: =INDEX('Name pool'!A:A, RANDBETWEEN(2, COUNTA('Name pool'!A:A))) & " " & INDEX('Name pool'!B:B, RANDBETWEEN(2, COUNTA('Name pool'!B:B))) -> Varun Yadav | C7: Mumbai | D7: =CHOOSE(RANDBETWEEN(1,7),"BR01","BR02","BR03","BR04","BR05","BR06","BR07") -> BR03 | E7: =CHOOSE(RANDBETWEEN(1,3),"Basic","Standard","Premium") -> Standard | F7: 45669 | G7: 46034 | H7: 3500 | I7: =H7 * RANDBETWEEN(1,12) -> 31500 | J7: 1 | K7: =CHOOSE(RANDBETWEEN(1,2),"Yes","No") -> No | L7: =CHOOSE(RANDBETWEEN(1,3),"Weight Loss","Muscle Gain","General Fitness") -> Weight Loss | M7: =IF(J7<5,IF(RANDBETWEEN(1,100)<70,"Cancelled","Active"),"Active") -> Cancelled | N7: 46011 | Q7: =IF(RAND()<0.2, IF(RAND()<0.5, LOWER(C7), UPPER(C7)), C7 ) -> Mumbai | R7: =IF(RAND()<0.15, J7 & " visits", J7 ) -> 1 | S7: =IF(RAND()<0.1, TEXT(H7,"0"), H7 ) -> 3500 | T7: =RANDBETWEEN(DATE(2023,1,1), DATE(2026,1,31)) -> 45732 | U7: =IF(AND(M7="Cancelled", RAND()<0.5), F7 + RANDBETWEEN(10,50), N7 ) -> 46011
A8: ="MEM" & TEXT(ROW()-1,"0000") -> MEM0007 | B8: =INDEX('Name pool'!A:A, RANDBETWEEN(2, COUNTA('Name pool'!A:A))) & " " & INDEX('Name pool'!B:B, RANDBETWEEN(2, COUNTA('Name pool'!B:B))) -> Zara Joshi | C8: Kochi | D8: =CHOOSE(RANDBETWEEN(1,7),"BR01","BR02","BR03","BR04","BR05","BR06","BR07") -> BR01 | E8: =CHOOSE(RANDBETWEEN(1,3),"Basic","Standard","Premium") -> Standard | F8: 45116 | G8: 45146 | H8: 3500 | I8: =H8 * RANDBETWEEN(1,12) -> 17500 | J8: 7 | K8: =CHOOSE(RANDBETWEEN(1,2),"Yes","No") -> No | L8: =CHOOSE(RANDBETWEEN(1,3),"Weight Loss","Muscle Gain","General Fitness") -> Weight Loss | M8: =IF(J8<5,IF(RANDBETWEEN(1,100)<70,"Cancelled","Active"),"Active") -> Active | N8: 45649 | Q8: =IF(RAND()<0.2, IF(RAND()<0.5, LOWER(C8), UPPER(C8)), C8 ) -> kochi | R8: =IF(RAND()<0.15, J8 & " visits", J8 ) -> 7 | S8: =IF(RAND()<0.1, TEXT(H8,"0"), H8 ) -> 3500 | T8: =RANDBETWEEN(DATE(2023,1,1), DATE(2026,1,31)) -> 45818 | U8: =IF(AND(M8="Cancelled", RAND()<0.5), F8 + RANDBETWEEN(10,50), N8 ) -> 45649
A9: ="MEM" & TEXT(ROW()-1,"0000") -> MEM0008 | B9: =INDEX('Name pool'!A:A, RANDBETWEEN(2, COUNTA('Name pool'!A:A))) & " " & INDEX('Name pool'!B:B, RANDBETWEEN(2, COUNTA('Name pool'!B:B))) -> Aditya Khan | C9: Calicut | D9: =CHOOSE(RANDBETWEEN(1,7),"BR01","BR02","BR03","BR04","BR05","BR06","BR07") -> BR01 | E9: =CHOOSE(RANDBETWEEN(1,3),"Basic","Standard","Premium") -> Standard | F9: 45986 | G9: 46076 | H9: 1000 | I9: =H9 * RANDBETWEEN(1,12) -> 3000 | J9: 8 visits | K9: =CHOOSE(RANDBETWEEN(1,2),"Yes","No") -> No | L9: =CHOOSE(RANDBETWEEN(1,3),"Weight Loss","Muscle Gain","General Fitness") -> Muscle Gain | M9: =IF(J9<5,IF(RANDBETWEEN(1,100)<70,"Cancelled","Active"),"Active") -> Active | N9: 46071 | Q9: =IF(RAND()<0.2, IF(RAND()<0.5, LOWER(C9), UPPER(C9)), C9 ) -> Calicut | R9: =IF(RAND()<0.15, J9 & " visits", J9 ) -> 8 visits | S9: =IF(RAND()<0.1, TEXT(H9,"0"), H9 ) -> 1000 | T9: =RANDBETWEEN(DATE(2023,1,1), DATE(2026,1,31)) -> 45392 | U9: =IF(AND(M9="Cancelled", RAND()<0.5), F9 + RANDBETWEEN(10,50), N9 ) -> 46071
A10: ="MEM" & TEXT(ROW()-1,"0000") -> MEM0009 | B10: =INDEX('Name pool'!A:A, RANDBETWEEN(2, COUNTA('Name pool'!A:A))) & " " & INDEX('Name pool'!B:B, RANDBETWEEN(2, COUNTA('Name pool'!B:B))) -> Lakshmi Shetty | C10: Bangalore | D10: =CHOOSE(RANDBETWEEN(1,7),"BR01","BR02","BR03","BR04","BR05","BR06","BR07") -> BR06 | E10: =CHOOSE(RANDBETWEEN(1,3),"Basic","Standard","Premium") -> Premium | F10: 45552 | G10: 45582 | H10: 2000 | I10: =H10 * RANDBETWEEN(1,12) -> 4000 | J10: 14 visits | K10: =CHOOSE(RANDBETWEEN(1,2),"Yes","No") -> Yes | L10: =CHOOSE(RANDBETWEEN(1,3),"Weight Loss","Muscle Gain","General Fitness") -> General Fitness | M10: =IF(J10<5,IF(RANDBETWEEN(1,100)<70,"Cancelled","Active"),"Active") -> Active | N10: 45846 | Q10: =IF(RAND()<0.2, IF(RAND()<0.5, LOWER(C10), UPPER(C10)), C10 ) -> BANGALORE | R10: =IF(RAND()<0.15, J10 & " visits", J10 ) -> 14 visits | S10: =IF(RAND()<0.1, TEXT(H10,"0"), H10 ) -> 2000 | T10: =RANDBETWEEN(DATE(2023,1,1), DATE(2026,1,31)) -> 45098 | U10: =IF(AND(M10="Cancelled", RAND()<0.5), F10 + RANDBETWEEN(10,50), N10 ) -> 45846
A11: ="MEM" & TEXT(ROW()-1,"0000") -> MEM0010 | B11: =INDEX('Name pool'!A:A, RANDBETWEEN(2, COUNTA('Name pool'!A:A))) & " " & INDEX('Name pool'!B:B, RANDBETWEEN(2, COUNTA('Name pool'!B:B))) -> Pooja Iyer | C11: Mumbai | D11: =CHOOSE(RANDBETWEEN(1,7),"BR01","BR02","BR03","BR04","BR05","BR06","BR07") -> BR03 | E11: =CHOOSE(RANDBETWEEN(1,3),"Basic","Standard","Premium") -> Basic | F11: 45390 | G11: 45420 | H11: 3500 | I11: =H11 * RANDBETWEEN(1,12) -> 24500 | J11: 15 | K11: =CHOOSE(RANDBETWEEN(1,2),"Yes","No") -> Yes | L11: =CHOOSE(RANDBETWEEN(1,3),"Weight Loss","Muscle Gain","General Fitness") -> Muscle Gain | M11: =IF(J11<5,IF(RANDBETWEEN(1,100)<70,"Cancelled","Active"),"Active") -> Active | N11: 45926 | Q11: =IF(RAND()<0.2, IF(RAND()<0.5, LOWER(C11), UPPER(C11)), C11 ) -> Mumbai | R11: =IF(RAND()<0.15, J11 & " visits", J11 ) -> 15 visits | S11: =IF(RAND()<0.1, TEXT(H11,"0"), H11 ) -> 3500 | T11: =RANDBETWEEN(DATE(2023,1,1), DATE(2026,1,31)) -> 45002 | U11: =IF(AND(M11="Cancelled", RAND()<0.5), F11 + RANDBETWEEN(10,50), N11 ) -> 45926
A12: ="MEM" & TEXT(ROW()-1,"0000") -> MEM0011 | B12: =INDEX('Name pool'!A:A, RANDBETWEEN(2, COUNTA('Name pool'!A:A))) & " " & INDEX('Name pool'!B:B, RANDBETWEEN(2, COUNTA('Name pool'!B:B))) -> Siddharth Shaikh | C12: Mumbai | D12: =CHOOSE(RANDBETWEEN(1,7),"BR01","BR02","BR03","BR04","BR05","BR06","BR07") -> BR01 | E12: =CHOOSE(RANDBETWEEN(1,3),"Basic","Standard","Premium") -> Standard | F12: 45093 | G12: 45458 | H12: 2000 | I12: =H12 * RANDBETWEEN(1,12) -> 2000 | J12: 23 visits | K12: =CHOOSE(RANDBETWEEN(1,2),"Yes","No") -> Yes | L12: =CHOOSE(RANDBETWEEN(1,3),"Weight Loss","Muscle Gain","General Fitness") -> General Fitness | M12: =IF(J12<5,IF(RANDBETWEEN(1,100)<70,"Cancelled","Active"),"Active") -> Active | N12: 45535 | Q12: =IF(RAND()<0.2, IF(RAND()<0.5, LOWER(C12), UPPER(C12)), C12 ) -> Mumbai | R12: =IF(RAND()<0.15, J12 & " visits", J12 ) -> 23 visits | S12: =IF(RAND()<0.1, TEXT(H12,"0"), H12 ) -> 2000 | T12: =RANDBETWEEN(DATE(2023,1,1), DATE(2026,1,31)) -> 45643 | U12: =IF(AND(M12="Cancelled", RAND()<0.5), F12 + RANDBETWEEN(10,50), N12 ) -> 45535
A13: ="MEM" & TEXT(ROW()-1,"0000") -> MEM0012 | B13: =INDEX('Name pool'!A:A, RANDBETWEEN(2, COUNTA('Name pool'!A:A))) & " " & INDEX('Name pool'!B:B, RANDBETWEEN(2, COUNTA('Name pool'!B:B))) -> Ishita Nambiar | C13: HYDERABAD | D13: =CHOOSE(RANDBETWEEN(1,7),"BR01","BR02","BR03","BR04","BR05","BR06","BR07") -> BR06 | E13: =CHOOSE(RANDBETWEEN(1,3),"Basic","Standard","Premium") -> Basic | F13: 45363 | G13: 45728 | H13: 2000 | I13: =H13 * RANDBETWEEN(1,12) -> 24000 | J13: 14 | K13: =CHOOSE(RANDBETWEEN(1,2),"Yes","No") -> Yes | L13: =CHOOSE(RANDBETWEEN(1,3),"Weight Loss","Muscle Gain","General Fitness") -> Weight Loss | M13: =IF(J13<5,IF(RANDBETWEEN(1,100)<70,"Cancelled","Active"),"Active") -> Active | N13: 46031 | Q13: =IF(RAND()<0.2, IF(RAND()<0.5, LOWER(C13), UPPER(C13)), C13 ) -> HYDERABAD | R13: =IF(RAND()<0.15, J13 & " visits", J13 ) -> 14 | S13: =IF(RAND()<0.1, TEXT(H13,"0"), H13 ) -> 2000 | T13: =RANDBETWEEN(DATE(2023,1,1), DATE(2026,1,31)) -> 45090 | U13: =IF(AND(M13="Cancelled", RAND()<0.5), F13 + RANDBETWEEN(10,50), N13 ) -> 46031
A14: ="MEM" & TEXT(ROW()-1,"0000") -> MEM0013 | B14: =INDEX('Name pool'!A:A, RANDBETWEEN(2, COUNTA('Name pool'!A:A))) & " " & INDEX('Name pool'!B:B, RANDBETWEEN(2, COUNTA('Name pool'!B:B))) -> Aditya Fernandes | C14: Chennai | D14: =CHOOSE(RANDBETWEEN(1,7),"BR01","BR02","BR03","BR04","BR05","BR06","BR07") -> BR05 | E14: =CHOOSE(RANDBETWEEN(1,3),"Basic","Standard","Premium") -> Premium | F14: 45518 | G14: 45548 | H14: 1000 | I14: =H14 * RANDBETWEEN(1,12) -> 2000 | J14: 15 | K14: =CHOOSE(RANDBETWEEN(1,2),"Yes","No") -> No | L14: =CHOOSE(RANDBETWEEN(1,3),"Weight Loss","Muscle Gain","General Fitness") -> General Fitness | M14: =IF(J14<5,IF(RANDBETWEEN(1,100)<70,"Cancelled","Active"),"Active") -> Active | N14: 45895 | Q14: =IF(RAND()<0.2, IF(RAND()<0.5, LOWER(C14), UPPER(C14)), C14 ) -> Chennai | R14: =IF(RAND()<0.15, J14 & " visits", J14 ) -> 15 | S14: =IF(RAND()<0.1, TEXT(H14,"0"), H14 ) -> 1000 | T14: =RANDBETWEEN(DATE(2023,1,1), DATE(2026,1,31)) -> 46041 | U14: =IF(AND(M14="Cancelled", RAND()<0.5), F14 + RANDBETWEEN(10,50), N14 ) -> 45895
A15: ="MEM" & TEXT(ROW()-1,"0000") -> MEM0014 | B15: =INDEX('Name pool'!A:A, RANDBETWEEN(2, COUNTA('Name pool'!A:A))) & " " & INDEX('Name pool'!B:B, RANDBETWEEN(2, COUNTA('Name pool'!B:B))) -> Pooja Agarwal | C15: Calicut | D15: =CHOOSE(RANDBETWEEN(1,7),"BR01","BR02","BR03","BR04","BR05","BR06","BR07") -> BR03 | E15: =CHOOSE(RANDBETWEEN(1,3),"Basic","Standard","Premium") -> Premium | F15: 45394 | G15: 45484 | H15: 1000 | I15: =H15 * RANDBETWEEN(1,12) -> 9000 | J15: 10 | K15: =CHOOSE(RANDBETWEEN(1,2),"Yes","No") -> No | L15: =CHOOSE(RANDBETWEEN(1,3),"Weight Loss","Muscle Gain","General Fitness") -> General Fitness | M15: =IF(J15<5,IF(RANDBETWEEN(1,100)<70,"Cancelled","Active"),"Active") -> Active | N15: 45802 | Q15: =IF(RAND()<0.2, IF(RAND()<0.5, LOWER(C15), UPPER(C15)), C15 ) -> Calicut | R15: =IF(RAND()<0.15, J15 & " visits", J15 ) -> 10 | S15: =IF(RAND()<0.1, TEXT(H15,"0"), H15 ) -> 1000 | T15: =RANDBETWEEN(DATE(2023,1,1), DATE(2026,1,31)) -> 45897 | U15: =IF(AND(M15="Cancelled", RAND()<0.5), F15 + RANDBETWEEN(10,50), N15 ) -> 45802
A16: ="MEM" & TEXT(ROW()-1,"0000") -> MEM0015 | B16: =INDEX('Name pool'!A:A, RANDBETWEEN(2, COUNTA('Name pool'!A:A))) & " " & INDEX('Name pool'!B:B, RANDBETWEEN(2, COUNTA('Name pool'!B:B))) -> Nikhil Verma | C16: Bangalore | D16: =CHOOSE(RANDBETWEEN(1,7),"BR01","BR02","BR03","BR04","BR05","BR06","BR07") -> BR05 | E16: =CHOOSE(RANDBETWEEN(1,3),"Basic","Standard","Premium") -> Standard | F16: 45496 | G16: 45861 | H16: 1000 | I16: =H16 * RANDBETWEEN(1,12) -> 8000 | J16: 21 | K16: =CHOOSE(RANDBETWEEN(1,2),"Yes","No") -> Yes | L16: =CHOOSE(RANDBETWEEN(1,3),"Weight Loss","Muscle Gain","General Fitness") -> Weight Loss | M16: =IF(J16<5,IF(RANDBETWEEN(1,100)<70,"Cancelled","Active"),"Active") -> Active | N16: 46003 | Q16: =IF(RAND()<0.2, IF(RAND()<0.5, LOWER(C16), UPPER(C16)), C16 ) -> Bangalore | R16: =IF(RAND()<0.15, J16 & " visits", J16 ) -> 21 | S16: =IF(RAND()<0.1, TEXT(H16,"0"), H16 ) -> 1000 | T16: =RANDBETWEEN(DATE(2023,1,1), DATE(2026,1,31)) -> 45695 | U16: =IF(AND(M16="Cancelled", RAND()<0.5), F16 + RANDBETWEEN(10,50), N16 ) -> 46003
A17: ="MEM" & TEXT(ROW()-1,"0000") -> MEM0016 | B17: =INDEX('Name pool'!A:A, RANDBETWEEN(2, COUNTA('Name pool'!A:A))) & " " & INDEX('Name pool'!B:B, RANDBETWEEN(2, COUNTA('Name pool'!B:B))) -> Riya Kapoor | C17: Bangalore | D17: =CHOOSE(RANDBETWEEN(1,7),"BR01","BR02","BR03","BR04","BR05","BR06","BR07") -> BR01 | E17: =CHOOSE(RANDBETWEEN(1,3),"Basic","Standard","Premium") -> Premium | F17: 45689 | G17: 45719 | H17: 3500 | I17: =H17 * RANDBETWEEN(1,12) -> 42000 | J17: 6 | K17: =CHOOSE(RANDBETWEEN(1,2),"Yes","No") -> Yes | L17: =CHOOSE(RANDBETWEEN(1,3),"Weight Loss","Muscle Gain","General Fitness") -> Muscle Gain | M17: =IF(J17<5,IF(RANDBETWEEN(1,100)<70,"Cancelled","Active"),"Active") -> Active | N17: 45758 | Q17: =IF(RAND()<0.2, IF(RAND()<0.5, LOWER(C17), UPPER(C17)), C17 ) -> Bangalore | R17: =IF(RAND()<0.15, J17 & " visits", J17 ) -> 6 | S17: =IF(RAND()<0.1, TEXT(H17,"0"), H17 ) -> 3500 | T17: =RANDBETWEEN(DATE(2023,1,1), DATE(2026,1,31)) -> 46019 | U17: =IF(AND(M17="Cancelled", RAND()<0.5), F17 + RANDBETWEEN(10,50), N17 ) -> 45758
A18: ="MEM" & TEXT(ROW()-1,"0000") -> MEM0017 | B18: =INDEX('Name pool'!A:A, RANDBETWEEN(2, COUNTA('Name pool'!A:A))) & " " & INDEX('Name pool'!B:B, RANDBETWEEN(2, COUNTA('Name pool'!B:B))) -> Deepak Agarwal | C18: Kochi | D18: =CHOOSE(RANDBETWEEN(1,7),"BR01","BR02","BR03","BR04","BR05","BR06","BR07") -> BR04 | E18: =CHOOSE(RANDBETWEEN(1,3),"Basic","Standard","Premium") -> Basic | F18: 45358 | G18: 45723 | H18: 3500 | I18: =H18 * RANDBETWEEN(1,12) -> 24500 | J18: 16 | K18: =CHOOSE(RANDBETWEEN(1,2),"Yes","No") -> Yes | L18: =CHOOSE(RANDBETWEEN(1,3),"Weight Loss","Muscle Gain","General Fitness") -> General Fitness | M18: =IF(J18<5,IF(RANDBETWEEN(1,100)<70,"Cancelled","Active"),"Active") -> Active | N18: 45412 | Q18: =IF(RAND()<0.2, IF(RAND()<0.5, LOWER(C18), UPPER(C18)), C18 ) -> Kochi | R18: =IF(RAND()<0.15, J18 & " visits", J18 ) -> 16 | S18: =IF(RAND()<0.1, TEXT(H18,"0"), H18 ) -> 3500 | T18: =RANDBETWEEN(DATE(2023,1,1), DATE(2026,1,31)) -> 45201 | U18: =IF(AND(M18="Cancelled", RAND()<0.5), F18 + RANDBETWEEN(10,50), N18 ) -> 45412
A19: ="MEM" & TEXT(ROW()-1,"0000") -> MEM0018 | B19: =INDEX('Name pool'!A:A, RANDBETWEEN(2, COUNTA('Name pool'!A:A))) & " " & INDEX('Name pool'!B:B, RANDBETWEEN(2, COUNTA('Name pool'!B:B))) -> Ankit Naidu | C19: Chennai | D19: =CHOOSE(RANDBETWEEN(1,7),"BR01","BR02","BR03","BR04","BR05","BR06","BR07") -> BR02 | E19: =CHOOSE(RANDBETWEEN(1,3),"Basic","Standard","Premium") -> Premium | F19: 45872 | G19: 46237 | H19: 3500 | I19: =H19 * RANDBETWEEN(1,12) -> 38500 | J19: 14 | K19: =CHOOSE(RANDBETWEEN(1,2),"Yes","No") -> Yes | L19: =CHOOSE(RANDBETWEEN(1,3),"Weight Loss","Muscle Gain","General Fitness") -> Muscle Gain | M19: =IF(J19<5,IF(RANDBETWEEN(1,100)<70,"Cancelled","Active"),"Active") -> Active | N19: 46059 | Q19: =IF(RAND()<0.2, IF(RAND()<0.5, LOWER(C19), UPPER(C19)), C19 ) -> chennai | R19: =IF(RAND()<0.15, J19 & " visits", J19 ) -> 14 visits | S19: =IF(RAND()<0.1, TEXT(H19,"0"), H19 ) -> 3500 | T19: =RANDBETWEEN(DATE(2023,1,1), DATE(2026,1,31)) -> 45559 | U19: =IF(AND(M19="Cancelled", RAND()<0.5), F19 + RANDBETWEEN(10,50), N19 ) -> 46059
A20: ="MEM" & TEXT(ROW()-1,"0000") -> MEM0019 | B20: =INDEX('Name pool'!A:A, RANDBETWEEN(2, COUNTA('Name pool'!A:A))) & " " & INDEX('Name pool'!B:B, RANDBETWEEN(2, COUNTA('Name pool'!B:B))) -> Fatima Gupta | C20: Calicut | D20: =CHOOSE(RANDBETWEEN(1,7),"BR01","BR02","BR03","BR04","BR05","BR06","BR07") -> BR07 | E20: =CHOOSE(RANDBETWEEN(1,3),"Basic","Standard","Premium") -> Basic | F20: 45429 | G20: 45459 | H20: 3500 | I20: =H20 * RANDBETWEEN(1,12) -> 24500 | J20: 23 | K20: =CHOOSE(RANDBETWEEN(1,2),"Yes","No") -> Yes | L20: =CHOOSE(RANDBETWEEN(1,3),"Weight Loss","Muscle Gain","General Fitness") -> General Fitness | M20: =IF(J20<5,IF(RANDBETWEEN(1,100)<70,"Cancelled","Active"),"Active") -> Active | N20: 46072 | Q20: =IF(RAND()<0.2, IF(RAND()<0.5, LOWER(C20), UPPER(C20)), C20 ) -> calicut | R20: =IF(RAND()<0.15, J20 & " visits", J20 ) -> 23 | S20: =IF(RAND()<0.1, TEXT(H20,"0"), H20 ) -> 3500 | T20: =RANDBETWEEN(DATE(2023,1,1), DATE(2026,1,31)) -> 45370 | U20: =IF(AND(M20="Cancelled", RAND()<0.5), F20 + RANDBETWEEN(10,50), N20 ) -> 46072
A21: ="MEM" & TEXT(ROW()-1,"0000") -> MEM0020 | B21: =INDEX('Name pool'!A:A, RANDBETWEEN(2, COUNTA('Name pool'!A:A))) & " " & INDEX('Name pool'!B:B, RANDBETWEEN(2, COUNTA('Name pool'!B:B))) -> Priya Gupta | C21: Trivandrum | D21: =CHOOSE(RANDBETWEEN(1,7),"BR01","BR02","BR03","BR04","BR05","BR06","BR07") -> BR06 | E21: =CHOOSE(RANDBETWEEN(1,3),"Basic","Standard","Premium") -> Basic | F21: 44974 | G21: 45004 | H21: 2000 | I21: =H21 * RANDBETWEEN(1,12) -> 6000 | J21: 19 | K21: =CHOOSE(RANDBETWEEN(1,2),"Yes","No") -> Yes | L21: =CHOOSE(RANDBETWEEN(1,3),"Weight Loss","Muscle Gain","General Fitness") -> Weight Loss | M21: =IF(J21<5,IF(RANDBETWEEN(1,100)<70,"Cancelled","Active"),"Active") -> Active | N21: 45123 | Q21: =IF(RAND()<0.2, IF(RAND()<0.5, LOWER(C21), UPPER(C21)), C21 ) -> Trivandrum | R21: =IF(RAND()<0.15, J21 & " visits", J21 ) -> 19 | S21: =IF(RAND()<0.1, TEXT(H21,"0"), H21 ) -> 2000 | T21: =RANDBETWEEN(DATE(2023,1,1), DATE(2026,1,31)) -> 45143 | U21: =IF(AND(M21="Cancelled", RAND()<0.5), F21 + RANDBETWEEN(10,50), N21 ) -> 45123
A22: ="MEM" & TEXT(ROW()-1,"0000") -> MEM0021 | B22: =INDEX('Name pool'!A:A, RANDBETWEEN(2, COUNTA('Name pool'!A:A))) & " " & INDEX('Name pool'!B:B, RANDBETWEEN(2, COUNTA('Name pool'!B:B))) -> Rohit Singh | C22: Trivandrum | D22: =CHOOSE(RANDBETWEEN(1,7),"BR01","BR02","BR03","BR04","BR05","BR06","BR07") -> BR07 | E22: =CHOOSE(RANDBETWEEN(1,3),"Basic","Standard","Premium") -> Basic | F22: 45629 | G22: 45659 | H22: 3500 | I22: =H22 * RANDBETWEEN(1,12) -> 3500 | J22: 17 visits | K22: =CHOOSE(RANDBETWEEN(1,2),"Yes","No") -> No | L22: =CHOOSE(RANDBETWEEN(1,3),"Weight Loss","Muscle Gain","General Fitness") -> Weight Loss | M22: =IF(J22<5,IF(RANDBETWEEN(1,100)<70,"Cancelled","Active"),"Active") -> Active | N22: 45950 | Q22: =IF(RAND()<0.2, IF(RAND()<0.5, LOWER(C22), UPPER(C22)), C22 ) -> Trivandrum | R22: =IF(RAND()<0.15, J22 & " visits", J22 ) -> 17 visits visits | S22: =IF(RAND()<0.1, TEXT(H22,"0"), H22 ) -> 3500 | T22: =RANDBETWEEN(DATE(2023,1,1), DATE(2026,1,31)) -> 45979 | U22: =IF(AND(M22="Cancelled", RAND()<0.5), F22 + RANDBETWEEN(10,50), N22 ) -> 45950
A23: ="MEM" & TEXT(ROW()-1,"0000") -> MEM0022 | B23: =INDEX('Name pool'!A:A, RANDBETWEEN(2, COUNTA('Name pool'!A:A))) & " " & INDEX('Name pool'!B:B, RANDBETWEEN(2, COUNTA('Name pool'!B:B))) -> Zara Menon | C23: trivandrum | D23: =CHOOSE(RANDBETWEEN(1,7),"BR01","BR02","BR03","BR04","BR05","BR06","BR07") -> BR04 | E23: =CHOOSE(RANDBETWEEN(1,3),"Basic","Standard","Premium") -> Basic | F23: 45326 | G23: 45356 | H23: 1000 | I23: =H23 * RANDBETWEEN(1,12) -> 2000 | J23: 18 | K23: =CHOOSE(RANDBETWEEN(1,2),"Yes","No") -> Yes | L23: =CHOOSE(RANDBETWEEN(1,3),"Weight Loss","Muscle Gain","General Fitness") -> General Fitness | M23: =IF(J23<5,IF(RANDBETWEEN(1,100)<70,"Cancelled","Active"),"Active") -> Active | N23: 45865 | Q23: =IF(RAND()<0.2, IF(RAND()<0.5, LOWER(C23), UPPER(C23)), C23 ) -> TRIVANDRUM | R23: =IF(RAND()<0.15, J23 & " visits", J23 ) -> 18 visits | S23: =IF(RAND()<0.1, TEXT(H23,"0"), H23 ) -> 1000 | T23: =RANDBETWEEN(DATE(2023,1,1), DATE(2026,1,31)) -> 45518 | U23: =IF(AND(M23="Cancelled", RAND()<0.5), F23 + RANDBETWEEN(10,50), N23 ) -> 45865
A24: ="MEM" & TEXT(ROW()-1,"0000") -> MEM0023 | B24: =INDEX('Name pool'!A:A, RANDBETWEEN(2, COUNTA('Name pool'!A:A))) & " " & INDEX('Name pool'!B:B, RANDBETWEEN(2, COUNTA('Name pool'!B:B))) -> Harish Desai | C24: Bangalore | D24: =CHOOSE(RANDBETWEEN(1,7),"BR01","BR02","BR03","BR04","BR05","BR06","BR07") -> BR07 | E24: =CHOOSE(RANDBETWEEN(1,3),"Basic","Standard","Premium") -> Basic | F24: 45858 | G24: 46223 | H24: 1000 | I24: =H24 * RANDBETWEEN(1,12) -> 5000 | J24: 9 | K24: =CHOOSE(RANDBETWEEN(1,2),"Yes","No") -> Yes | L24: =CHOOSE(RANDBETWEEN(1,3),"Weight Loss","Muscle Gain","General Fitness") -> General Fitness | M24: =IF(J24<5,IF(RANDBETWEEN(1,100)<70,"Cancelled","Active"),"Active") -> Active | N24: 46102 | Q24: =IF(RAND()<0.2, IF(RAND()<0.5, LOWER(C24), UPPER(C24)), C24 ) -> Bangalore | R24: =IF(RAND()<0.15, J24 & " visits", J24 ) -> 9 | S24: =IF(RAND()<0.1, TEXT(H24,"0"), H24 ) -> 1000 | T24: =RANDBETWEEN(DATE(2023,1,1), DATE(2026,1,31)) -> 45922 | U24: =IF(AND(M24="Cancelled", RAND()<0.5), F24 + RANDBETWEEN(10,50), N24 ) -> 46102
A25: ="MEM" & TEXT(ROW()-1,"0000") -> MEM0024 | B25: =INDEX('Name pool'!A:A, RANDBETWEEN(2, COUNTA('Name pool'!A:A))) & " " & INDEX('Name pool'!B:B, RANDBETWEEN(2, COUNTA('Name pool'!B:B))) -> Harish Desai | C25: Kochi | D25: =CHOOSE(RANDBETWEEN(1,7),"BR01","BR02","BR03","BR04","BR05","BR06","BR07") -> BR03 | E25: =CHOOSE(RANDBETWEEN(1,3),"Basic","Standard","Premium") -> Basic | F25: 45814 | G25: 45904 | H25: 1000 | I25: =H25 * RANDBETWEEN(1,12) -> 5000 | J25: 4 | K25: =CHOOSE(RANDBETWEEN(1,2),"Yes","No") -> No | L25: =CHOOSE(RANDBETWEEN(1,3),"Weight Loss","Muscle Gain","General Fitness") -> Weight Loss | M25: =IF(J25<5,IF(RANDBETWEEN(1,100)<70,"Cancelled","Active"),"Active") -> Active | N25: 45855 | Q25: =IF(RAND()<0.2, IF(RAND()<0.5, LOWER(C25), UPPER(C25)), C25 ) -> kochi | R25: =IF(RAND()<0.15, J25 & " visits", J25 ) -> 4 | S25: =IF(RAND()<0.1, TEXT(H25,"0"), H25 ) -> 1000 | T25: =RANDBETWEEN(DATE(2023,1,1), DATE(2026,1,31)) -> 44937 | U25: =IF(AND(M25="Cancelled", RAND()<0.5), F25 + RANDBETWEEN(10,50), N25 ) -> 45855
A26: ="MEM" & TEXT(ROW()-1,"0000") -> MEM0025 | B26: =INDEX('Name pool'!A:A, RANDBETWEEN(2, COUNTA('Name pool'!A:A))) & " " & INDEX('Name pool'!B:B, RANDBETWEEN(2, COUNTA('Name pool'!B:B))) -> Ayesha Nair | C26: Hyderabad | D26: =CHOOSE(RANDBETWEEN(1,7),"BR01","BR02","BR03","BR04","BR05","BR06","BR07") -> BR07 | E26: =CHOOSE(RANDBETWEEN(1,3),"Basic","Standard","Premium") -> Standard | F26: 45963 | G26: 46328 | H26: 1000 | I26: =H26 * RANDBETWEEN(1,12) -> 4000 | J26: 13 | K26: =CHOOSE(RANDBETWEEN(1,2),"Yes","No") -> Yes | L26: =CHOOSE(RANDBETWEEN(1,3),"Weight Loss","Muscle Gain","General Fitness") -> General Fitness | M26: =IF(J26<5,IF(RANDBETWEEN(1,100)<70,"Cancelled","Active"),"Active") -> Active | N26: 46058 | Q26: =IF(RAND()<0.2, IF(RAND()<0.5, LOWER(C26), UPPER(C26)), C26 ) -> Hyderabad | R26: =IF(RAND()<0.15, J26 & " visits", J26 ) -> 13 | S26: =IF(RAND()<0.1, TEXT(H26,"0"), H26 ) -> 1000 | T26: =RANDBETWEEN(DATE(2023,1,1), DATE(2026,1,31)) -> 45163 | U26: =IF(AND(M26="Cancelled", RAND()<0.5), F26 + RANDBETWEEN(10,50), N26 ) -> 46058
A27: ="MEM" & TEXT(ROW()-1,"0000") -> MEM0026 | B27: =INDEX('Name pool'!A:A, RANDBETWEEN(2, COUNTA('Name pool'!A:A))) & " " & INDEX('Name pool'!B:B, RANDBETWEEN(2, COUNTA('Name pool'!B:B))) -> Shreya Lewis | C27: Chennai | D27: =CHOOSE(RANDBETWEEN(1,7),"BR01","BR02","BR03","BR04","BR05","BR06","BR07") -> BR04 | E27: =CHOOSE(RANDBETWEEN(1,3),"Basic","Standard","Premium") -> Premium | F27: 45571 | G27: 45661 | H27: 3500 | I27: =H27 * RANDBETWEEN(1,12) -> 21000 | J27: 12 | K27: =CHOOSE(RANDBETWEEN(1,2),"Yes","No") -> No | L27: =CHOOSE(RANDBETWEEN(1,3),"Weight Loss","Muscle Gain","General Fitness") -> Muscle Gain | M27: =IF(J27<5,IF(RANDBETWEEN(1,100)<70,"Cancelled","Active"),"Active") -> Active | N27: 45686 | Q27: =IF(RAND()<0.2, IF(RAND()<0.5, LOWER(C27), UPPER(C27)), C27 ) -> Chennai | R27: =IF(RAND()<0.15, J27 & " visits", J27 ) -> 12 | S27: =IF(RAND()<0.1, TEXT(H27,"0"), H27 ) -> 3500 | T27: =RANDBETWEEN(DATE(2023,1,1), DATE(2026,1,31)) -> 45613 | U27: =IF(AND(M27="Cancelled", RAND()<0.5), F27 + RANDBETWEEN(10,50), N27 ) -> 45686
A28: ="MEM" & TEXT(ROW()-1,"0000") -> MEM0027 | B28: =INDEX('Name pool'!A:A, RANDBETWEEN(2, COUNTA('Name pool'!A:A))) & " " & INDEX('Name pool'!B:B, RANDBETWEEN(2, COUNTA('Name pool'!B:B))) -> Fatima Reddy | C28: Kochi | D28: =CHOOSE(RANDBETWEEN(1,7),"BR01","BR02","BR03","BR04","BR05","BR06","BR07") -> BR05 | E28: =CHOOSE(RANDBETWEEN(1,3),"Basic","Standard","Premium") -> Standard | F28: 44959 | G28: 44989 | H28: 3500 | I28: =H28 * RANDBETWEEN(1,12) -> 21000 | J28: 16 | K28: =CHOOSE(RANDBETWEEN(1,2),"Yes","No") -> No | L28: =CHOOSE(RANDBETWEEN(1,3),"Weight Loss","Muscle Gain","General Fitness") -> General Fitness | M28: =IF(J28<5,IF(RANDBETWEEN(1,100)<70,"Cancelled","Active"),"Active") -> Active | N28: 45950 | Q28: =IF(RAND()<0.2, IF(RAND()<0.5, LOWER(C28), UPPER(C28)), C28 ) -> Kochi | R28: =IF(RAND()<0.15, J28 & " visits", J28 ) -> 16 | S28: =IF(RAND()<0.1, TEXT(H28,"0"), H28 ) -> 3500 | T28: =RANDBETWEEN(DATE(2023,1,1), DATE(2026,1,31)) -> 45229 | U28: =IF(AND(M28="Cancelled", RAND()<0.5), F28 + RANDBETWEEN(10,50), N28 ) -> 45950
A29: ="MEM" & TEXT(ROW()-1,"0000") -> MEM0028 | B29: =INDEX('Name pool'!A:A, RANDBETWEEN(2, COUNTA('Name pool'!A:A))) & " " & INDEX('Name pool'!B:B, RANDBETWEEN(2, COUNTA('Name pool'!B:B))) -> Pooja Fernandes | C29: Chennai | D29: =CHOOSE(RANDBETWEEN(1,7),"BR01","BR02","BR03","BR04","BR05","BR06","BR07") -> BR07 | E29: =CHOOSE(RANDBETWEEN(1,3),"Basic","Standard","Premium") -> Standard | F29: 45097 | G29: 45462 | H29: 1000 | I29: =H29 * RANDBETWEEN(1,12) -> 10000 | J29: 17 | K29: =CHOOSE(RANDBETWEEN(1,2),"Yes","No") -> No | L29: =CHOOSE(RANDBETWEEN(1,3),"Weight Loss","Muscle Gain","General Fitness") -> Muscle Gain | M29: =IF(J29<5,IF(RANDBETWEEN(1,100)<70,"Cancelled","Active"),"Active") -> Active | N29: 45499 | Q29: =IF(RAND()<0.2, IF(RAND()<0.5, LOWER(C29), UPPER(C29)), C29 ) -> Chennai | R29: =IF(RAND()<0.15, J29 & " visits", J29 ) -> 17 | S29: =IF(RAND()<0.1, TEXT(H29,"0"), H29 ) -> 1000 | T29: =RANDBETWEEN(DATE(2023,1,1), DATE(2026,1,31)) -> 46030 | U29: =IF(AND(M29="Cancelled", RAND()<0.5), F29 + RANDBETWEEN(10,50), N29 ) -> 45499
A30: ="MEM" & TEXT(ROW()-1,"0000") -> MEM0029 | B30: =INDEX('Name pool'!A:A, RANDBETWEEN(2, COUNTA('Name pool'!A:A))) & " " & INDEX('Name pool'!B:B, RANDBETWEEN(2, COUNTA('Name pool'!B:B))) -> Siddharth Shetty | C30: Chennai | D30: =CHOOSE(RANDBETWEEN(1,7),"BR01","BR02","BR03","BR04","BR05","BR06","BR07") -> BR07 | E30: =CHOOSE(RANDBETWEEN(1,3),"Basic","Standard","Premium") -> Basic | F30: 45971 | G30: 46336 | H30: 3500 | I30: =H30 * RANDBETWEEN(1,12) -> 10500 | J30: 1 | K30: =CHOOSE(RANDBETWEEN(1,2),"Yes","No") -> No | L30: =CHOOSE(RANDBETWEEN(1,3),"Weight Loss","Muscle Gain","General Fitness") -> Muscle Gain | M30: =IF(J30<5,IF(RANDBETWEEN(1,100)<70,"Cancelled","Active"),"Active") -> Active | N30: 46110 | Q30: =IF(RAND()<0.2, IF(RAND()<0.5, LOWER(C30), UPPER(C30)), C30 ) -> Chennai | R30: =IF(RAND()<0.15, J30 & " visits", J30 ) -> 1 | S30: =IF(RAND()<0.1, TEXT(H30,"0"), H30 ) -> 3500 | T30: =RANDBETWEEN(DATE(2023,1,1), DATE(2026,1,31)) -> 45727 | U30: =IF(AND(M30="Cancelled", RAND()<0.5), F30 + RANDBETWEEN(10,50), N30 ) -> 46110
A31: ="MEM" & TEXT(ROW()-1,"0000") -> MEM0030 | B31: =INDEX('Name pool'!A:A, RANDBETWEEN(2, COUNTA('Name pool'!A:A))) & " " & INDEX('Name pool'!B:B, RANDBETWEEN(2, COUNTA('Name pool'!B:B))) -> Riya Gupta | C31: Bangalore | D31: =CHOOSE(RANDBETWEEN(1,7),"BR01","BR02","BR03","BR04","BR05","BR06","BR07") -> BR01 | E31: =CHOOSE(RANDBETWEEN(1,3),"Basic","Standard","Premium") -> Premium | F31: 44988 | G31: 45353 | H31: 3500 | I31: =H31 * RANDBETWEEN(1,12) -> 17500 | J31: 0 | K31: =CHOOSE(RANDBETWEEN(1,2),"Yes","No") -> Yes | L31: =CHOOSE(RANDBETWEEN(1,3),"Weight Loss","Muscle Gain","General Fitness") -> General Fitness | M31: =IF(J31<5,IF(RANDBETWEEN(1,100)<70,"Cancelled","Active"),"Active") -> Cancelled | N31: 45264 | Q31: =IF(RAND()<0.2, IF(RAND()<0.5, LOWER(C31), UPPER(C31)), C31 ) -> Bangalore | R31: =IF(RAND()<0.15, J31 & " visits", J31 ) -> 0 | S31: =IF(RAND()<0.1, TEXT(H31,"0"), H31 ) -> 3500 | T31: =RANDBETWEEN(DATE(2023,1,1), DATE(2026,1,31)) -> 45725 | U31: =IF(AND(M31="Cancelled", RAND()<0.5), F31 + RANDBETWEEN(10,50), N31 ) -> 45264
A32: ="MEM" & TEXT(ROW()-1,"0000") -> MEM0031 | B32: =INDEX('Name pool'!A:A, RANDBETWEEN(2, COUNTA('Name pool'!A:A))) & " " & INDEX('Name pool'!B:B, RANDBETWEEN(2, COUNTA('Name pool'!B:B))) -> Karthik George | C32: Bangalore | D32: =CHOOSE(RANDBETWEEN(1,7),"BR01","BR02","BR03","BR04","BR05","BR06","BR07") -> BR07 | E32: =CHOOSE(RANDBETWEEN(1,3),"Basic","Standard","Premium") -> Premium | F32: 45493 | G32: 45583 | H32: 2000 | I32: =H32 * RANDBETWEEN(1,12) -> 18000 | J32: 19 | K32: =CHOOSE(RANDBETWEEN(1,2),"Yes","No") -> No | L32: =CHOOSE(RANDBETWEEN(1,3),"Weight Loss","Muscle Gain","General Fitness") -> Muscle Gain | M32: =IF(J32<5,IF(RANDBETWEEN(1,100)<70,"Cancelled","Active"),"Active") -> Active | N32: 45827 | Q32: =IF(RAND()<0.2, IF(RAND()<0.5, LOWER(C32), UPPER(C32)), C32 ) -> Bangalore | R32: =IF(RAND()<0.15, J32 & " visits", J32 ) -> 19 | S32: =IF(RAND()<0.1, TEXT(H32,"0"), H32 ) -> 2000 | T32: =RANDBETWEEN(DATE(2023,1,1), DATE(2026,1,31)) -> 45058 | U32: =IF(AND(M32="Cancelled", RAND()<0.5), F32 + RANDBETWEEN(10,50), N32 ) -> 45827
A33: ="MEM" & TEXT(ROW()-1,"0000") -> MEM0032 | B33: =INDEX('Name pool'!A:A, RANDBETWEEN(2, COUNTA('Name pool'!A:A))) & " " & INDEX('Name pool'!B:B, RANDBETWEEN(2, COUNTA('Name pool'!B:B))) -> Meera Reddy | C33: Calicut | D33: =CHOOSE(RANDBETWEEN(1,7),"BR01","BR02","BR03","BR04","BR05","BR06","BR07") -> BR02 | E33: =CHOOSE(RANDBETWEEN(1,3),"Basic","Standard","Premium") -> Basic | F33: 45247 | G33: 45337 | H33: 3500 | I33: =H33 * RANDBETWEEN(1,12) -> 31500 | J33: 11 | K33: =CHOOSE(RANDBETWEEN(1,2),"Yes","No") -> No | L33: =CHOOSE(RANDBETWEEN(1,3),"Weight Loss","Muscle Gain","General Fitness") -> Muscle Gain | M33: =IF(J33<5,IF(RANDBETWEEN(1,100)<70,"Cancelled","Active"),"Active") -> Active | N33: 45987 | Q33: =IF(RAND()<0.2, IF(RAND()<0.5, LOWER(C33), UPPER(C33)), C33 ) -> Calicut | R33: =IF(RAND()<0.15, J33 & " visits", J33 ) -> 11 | S33: =IF(RAND()<0.1, TEXT(H33,"0"), H33 ) -> 3500 | T33: =RANDBETWEEN(DATE(2023,1,1), DATE(2026,1,31)) -> 45879 | U33: =IF(AND(M33="Cancelled", RAND()<0.5), F33 + RANDBETWEEN(10,50), N33 ) -> 45987
A34: ="MEM" & TEXT(ROW()-1,"0000") -> MEM0033 | B34: =INDEX('Name pool'!A:A, RANDBETWEEN(2, COUNTA('Name pool'!A:A))) & " " & INDEX('Name pool'!B:B, RANDBETWEEN(2, COUNTA('Name pool'!B:B))) -> Varun George | C34: Hyderabad | D34: =CHOOSE(RANDBETWEEN(1,7),"BR01","BR02","BR03","BR04","BR05","BR06","BR07") -> BR07 | E34: =CHOOSE(RANDBETWEEN(1,3),"Basic","Standard","Premium") -> Basic | F34: 45276 | G34: 45641 | H34: 2000 | I34: =H34 * RANDBETWEEN(1,12) -> 12000 | J34: 21 | K34: =CHOOSE(RANDBETWEEN(1,2),"Yes","No") -> Yes | L34: =CHOOSE(RANDBETWEEN(1,3),"Weight Loss","Muscle Gain","General Fitness") -> Muscle Gain | M34: =IF(J34<5,IF(RANDBETWEEN(1,100)<70,"Cancelled","Active"),"Active") -> Active | N34: 45981 | Q34: =IF(RAND()<0.2, IF(RAND()<0.5, LOWER(C34), UPPER(C34)), C34 ) -> Hyderabad | R34: =IF(RAND()<0.15, J34 & " visits", J34 ) -> 21 | S34: =IF(RAND()<0.1, TEXT(H34,"0"), H34 ) -> 2000 | T34: =RANDBETWEEN(DATE(2023,1,1), DATE(2026,1,31)) -> 45130 | U34: =IF(AND(M34="Cancelled", RAND()<0.5), F34 + RANDBETWEEN(10,50), N34 ) -> 45981
... A38: ="MEM" & TEXT(ROW()-1,"0000") -> MEM0037 | B38: =INDEX('Name pool'!A:A, RANDBETWEEN(2, COUNTA('Name pool'!A:A))) & " " & INDEX('Name pool'!B:B, RANDBETWEEN(2, COUNTA('Name pool'!B:B))) -> Ayesha Nair | C38: Kochi | D38: =CHOOSE(RANDBETWEEN(1,7),"BR01","BR02","BR03","BR04","BR05","BR06","BR07") -> BR05 | E38: =CHOOSE(RANDBETWEEN(1,3),"Basic","Standard","Premium") -> Standard | F38: 45855 | G38: 45945 | H38: 3500 | I38: =H38 * RANDBETWEEN(1,12) -> 3500 | J38: 13 | K38: =CHOOSE(RANDBETWEEN(1,2),"Yes","No") -> No | L38: =CHOOSE(RANDBETWEEN(1,3),"Weight Loss","Muscle Gain","General Fitness") -> Weight Loss | M38: =IF(J38<5,IF(RANDBETWEEN(1,100)<70,"Cancelled","Active"),"Active") -> Active | N38: 46053 | Q38: =IF(RAND()<0.2, IF(RAND()<0.5, LOWER(C38), UPPER(C38)), C38 ) -> Kochi | R38: =IF(RAND()<0.15, J38 & " visits", J38 ) -> 13 | S38: =IF(RAND()<0.1, TEXT(H38,"0"), H38 ) -> 3500 | T38: =RANDBETWEEN(DATE(2023,1,1), DATE(2026,1,31)) -> 45858 | U38: =IF(AND(M38="Cancelled", RAND()<0.5), F38 + RANDBETWEEN(10,50), N38 ) -> 46053
A39: ="MEM" & TEXT(ROW()-1,"0000") -> MEM0038 | B39: =INDEX('Name pool'!A:A, RANDBETWEEN(2, COUNTA('Name pool'!A:A))) & " " & INDEX('Name pool'!B:B, RANDBETWEEN(2, COUNTA('Name pool'!B:B))) -> Akash Mathew | C39: Chennai | D39: =CHOOSE(RANDBETWEEN(1,7),"BR01","BR02","BR03","BR04","BR05","BR06","BR07") -> BR02 | E39: =CHOOSE(RANDBETWEEN(1,3),"Basic","Standard","Premium") -> Basic | F39: 45673 | G39: 45763 | H39: 3500 | I39: =H39 * RANDBETWEEN(1,12) -> 17500 | J39: 13 | K39: =CHOOSE(RANDBETWEEN(1,2),"Yes","No") -> Yes | L39: =CHOOSE(RANDBETWEEN(1,3),"Weight Loss","Muscle Gain","General Fitness") -> Muscle Gain | M39: =IF(J39<5,IF(RANDBETWEEN(1,100)<70,"Cancelled","Active"),"Active") -> Active | N39: 45759 | Q39: =IF(RAND()<0.2, IF(RAND()<0.5, LOWER(C39), UPPER(C39)), C39 ) -> Chennai | R39: =IF(RAND()<0.15, J39 & " visits", J39 ) -> 13 | S39: =IF(RAND()<0.1, TEXT(H39,"0"), H39 ) -> 3500 | T39: =RANDBETWEEN(DATE(2023,1,1), DATE(2026,1,31)) -> 45670 | U39: =IF(AND(M39="Cancelled", RAND()<0.5), F39 + RANDBETWEEN(10,50), N39 ) -> 45759
A40: ="MEM" & TEXT(ROW()-1,"0000") -> MEM0039 | B40: =INDEX('Name pool'!A:A, RANDBETWEEN(2, COUNTA('Name pool'!A:A))) & " " & INDEX('Name pool'!B:B, RANDBETWEEN(2, COUNTA('Name pool'!B:B))) -> Neha Menon | C40: Hyderabad | D40: =CHOOSE(RANDBETWEEN(1,7),"BR01","BR02","BR03","BR04","BR05","BR06","BR07") -> BR04 | E40: =CHOOSE(RANDBETWEEN(1,3),"Basic","Standard","Premium") -> Basic | F40: 46018 | G40: 46048 | H40: 2000 | I40: =H40 * RANDBETWEEN(1,12) -> 12000 | J40: 15 | K40: =CHOOSE(RANDBETWEEN(1,2),"Yes","No") -> No | L40: =CHOOSE(RANDBETWEEN(1,3),"Weight Loss","Muscle Gain","General Fitness") -> General Fitness | M40: =IF(J40<5,IF(RANDBETWEEN(1,100)<70,"Cancelled","Active"),"Active") -> Active | N40: 46088 | Q40: =IF(RAND()<0.2, IF(RAND()<0.5, LOWER(C40), UPPER(C40)), C40 ) -> Hyderabad | R40: =IF(RAND()<0.15, J40 & " visits", J40 ) -> 15 | S40: =IF(RAND()<0.1, TEXT(H40,"0"), H40 ) -> 2000 | T40: =RANDBETWEEN(DATE(2023,1,1), DATE(2026,1,31)) -> 45150 | U40: =IF(AND(M40="Cancelled", RAND()<0.5), F40 + RANDBETWEEN(10,50), N40 ) -> 46088
A41: ="MEM" & TEXT(ROW()-1,"0000") -> MEM0040 | B41: =INDEX('Name pool'!A:A, RANDBETWEEN(2, COUNTA('Name pool'!A:A))) & " " & INDEX('Name pool'!B:B, RANDBETWEEN(2, COUNTA('Name pool'!B:B))) -> Lakshmi Chatterjee | C41: Hyderabad | D41: =CHOOSE(RANDBETWEEN(1,7),"BR01","BR02","BR03","BR04","BR05","BR06","BR07") -> BR03 | E41: =CHOOSE(RANDBETWEEN(1,3),"Basic","Standard","Premium") -> Premium | F41: 45987 | G41: 46352 | H41: 3500 | I41: =H41 * RANDBETWEEN(1,12) -> 42000 | J41: 15 | K41: =CHOOSE(RANDBETWEEN(1,2),"Yes","No") -> Yes | L41: =CHOOSE(RANDBETWEEN(1,3),"Weight Loss","Muscle Gain","General Fitness") -> General Fitness | M41: =IF(J41<5,IF(RANDBETWEEN(1,100)<70,"Cancelled","Active"),"Active") -> Active | N41: 46092 | Q41: =IF(RAND()<0.2, IF(RAND()<0.5, LOWER(C41), UPPER(C41)), C41 ) -> Hyderabad | R41: =IF(RAND()<0.15, J41 & " visits", J41 ) -> 15 | S41: =IF(RAND()<0.1, TEXT(H41,"0"), H41 ) -> 3500 | T41: =RANDBETWEEN(DATE(2023,1,1), DATE(2026,1,31)) -> 45459 | U41: =IF(AND(M41="Cancelled", RAND()<0.5), F41 + RANDBETWEEN(10,50), N41 ) -> 46092
A42: ="MEM" & TEXT(ROW()-1,"0000") -> MEM0041 | B42: =INDEX('Name pool'!A:A, RANDBETWEEN(2, COUNTA('Name pool'!A:A))) & " " & INDEX('Name pool'!B:B, RANDBETWEEN(2, COUNTA('Name pool'!B:B))) -> Aditya Bhat | C42: Calicut | D42: =CHOOSE(RANDBETWEEN(1,7),"BR01","BR02","BR03","BR04","BR05","BR06","BR07") -> BR05 | E42: =CHOOSE(RANDBETWEEN(1,3),"Basic","Standard","Premium") -> Standard | F42: 45459 | G42: 45824 | H42: 1000 | I42: =H42 * RANDBETWEEN(1,12) -> 10000 | J42: 17 | K42: =CHOOSE(RANDBETWEEN(1,2),"Yes","No") -> Yes | L42: =CHOOSE(RANDBETWEEN(1,3),"Weight Loss","Muscle Gain","General Fitness") -> General Fitness | M42: =IF(J42<5,IF(RANDBETWEEN(1,100)<70,"Cancelled","Active"),"Active") -> Active | N42: 45590 | Q42: =IF(RAND()<0.2, IF(RAND()<0.5, LOWER(C42), UPPER(C42)), C42 ) -> Calicut | R42: =IF(RAND()<0.15, J42 & " visits", J42 ) -> 17 | S42: =IF(RAND()<0.1, TEXT(H42,"0"), H42 ) -> 1000 | T42: =RANDBETWEEN(DATE(2023,1,1), DATE(2026,1,31)) -> 45591 | U42: =IF(AND(M42="Cancelled", RAND()<0.5), F42 + RANDBETWEEN(10,50), N42 ) -> 45590
A43: ="MEM" & TEXT(ROW()-1,"0000") -> MEM0042 | B43: =INDEX('Name pool'!A:A, RANDBETWEEN(2, COUNTA('Name pool'!A:A))) & " " & INDEX('Name pool'!B:B, RANDBETWEEN(2, COUNTA('Name pool'!B:B))) -> Zara Verma | C43: Mumbai | D43: =CHOOSE(RANDBETWEEN(1,7),"BR01","BR02","BR03","BR04","BR05","BR06","BR07") -> BR03 | E43: =CHOOSE(RANDBETWEEN(1,3),"Basic","Standard","Premium") -> Premium | F43: 45171 | G43: 45201 | H43: 3500 | I43: =H43 * RANDBETWEEN(1,12) -> 7000 | J43: 20 | K43: =CHOOSE(RANDBETWEEN(1,2),"Yes","No") -> No | L43: =CHOOSE(RANDBETWEEN(1,3),"Weight Loss","Muscle Gain","General Fitness") -> General Fitness | M43: =IF(J43<5,IF(RANDBETWEEN(1,100)<70,"Cancelled","Active"),"Active") -> Active | N43: 46017 | Q43: =IF(RAND()<0.2, IF(RAND()<0.5, LOWER(C43), UPPER(C43)), C43 ) -> Mumbai | R43: =IF(RAND()<0.15, J43 & " visits", J43 ) -> 20 | S43: =IF(RAND()<0.1, TEXT(H43,"0"), H43 ) -> 3500 | T43: =RANDBETWEEN(DATE(2023,1,1), DATE(2026,1,31)) -> 45813 | U43: =IF(AND(M43="Cancelled", RAND()<0.5), F43 + RANDBETWEEN(10,50), N43 ) -> 46017
...

Sheet Cleaned_Data
A1: Member ID | B1: Member Name | C1: City | D1: Branch ID | E1: Membership Type | F1: Join Date | G1: Expiry Date | H1: Monthly Fee | I1: Total Payments | J1: Attendance | K1: Trainer Assigned | L1: Workout Goal | M1: Status | N1: Last Visit Date | P1: Duplicate_Flag | Q1: Data issue flag | R1: Last_Visit_Status
A2: =TRIM(CLEAN(Raw_Data!A2)) -> MEM0001 | B2: =TRIM(Raw_Data!B2) -> Karthik Joshi | C2: =_xlfn.XLOOKUP(D2, Branch_Master!A:A, Branch_Master!B:B) -> Calicut | D2: =TRIM(Raw_Data!D2) -> BR07 | E2: =PROPER(TRIM(Raw_Data!E2)) -> Premium | F2: =IFERROR(DATEVALUE(Raw_Data!F2), Raw_Data!F2) -> 45630 | G2: =IFERROR( IF( IFERROR(DATEVALUE(Raw_Data!G2), Raw_Data!G2) < IFERROR(DATEVALUE(Raw_Data!F2), Raw_Data!F2), IFERROR(DATEVALUE(Raw_Data!F2), Raw_Data!F2) + 30, IFERROR(DATEVALUE(Raw_Data!G2), Raw_Data!G2) ), "" ) -> 45660 | H2: =IFERROR(VALUE(Raw_Data!H2), "") -> 1000 | I2: =IFERROR(VALUE(Raw_Data!I2), "") -> 8000 | J2: =IFERROR( VALUE(SUBSTITUTE(Raw_Data!J2," visits","")), "" ) -> 18 | K2: =IF(TRIM(Raw_Data!K2)="","No",PROPER(TRIM(Raw_Data!K2))) -> No | L2: =PROPER(TRIM(Raw_Data!L2)) -> Weight Loss | M2: Active | N2: =IFERROR(DATEVALUE(Raw_Data!N2), Raw_Data!N2) -> 46022 | P2: =IF(COUNTIF($A$2:A2,A2)>1,"Duplicate","Unique") -> Unique | Q2: =IF(G2<F2,"Expiry Error", IF(AND(M2="Cancelled",N2<>""),"Cancelled but Active", IF(J2>30,"Invalid Attendance","OK"))) -> OK | R2: =IF(N2="","Missing","Available") -> Available
A3: =TRIM(CLEAN(Raw_Data!A3)) -> MEM0002 | B3: =TRIM(Raw_Data!B3) -> Meera George | C3: =_xlfn.XLOOKUP(D3, Branch_Master!A:A, Branch_Master!B:B) -> Kochi | D3: =TRIM(Raw_Data!D3) -> BR01 | E3: =PROPER(TRIM(Raw_Data!E3)) -> Basic | F3: =IFERROR(DATEVALUE(Raw_Data!F3), Raw_Data!F3) -> 45446 | G3: =IFERROR( IF( IFERROR(DATEVALUE(Raw_Data!G3), Raw_Data!G3) < IFERROR(DATEVALUE(Raw_Data!F3), Raw_Data!F3), IFERROR(DATEVALUE(Raw_Data!F3), Raw_Data!F3) + 30, IFERROR(DATEVALUE(Raw_Data!G3), Raw_Data!G3) ), "" ) -> 45536 | H3: =IFERROR(VALUE(Raw_Data!H3), "") -> 3500 | I3: =IFERROR(VALUE(Raw_Data!I3), "") -> 17500 | J3: =IFERROR( VALUE(SUBSTITUTE(Raw_Data!J3," visits","")), "" ) -> 0 | K3: =IF(TRIM(Raw_Data!K3)="","No",PROPER(TRIM(Raw_Data!K3))) -> No | L3: =PROPER(TRIM(Raw_Data!L3)) -> Muscle Gain | M3: Cancelled | N3: =IFERROR(DATEVALUE(Raw_Data!N3), Raw_Data!N3) -> 46050 | P3: =IF(COUNTIF($A$2:A3,A3)>1,"Duplicate","Unique") -> Unique | Q3: =IF(G3<F3,"Expiry Error", IF(AND(M3="Cancelled",N3<>""),"Cancelled but Active", IF(J3>30,"Invalid Attendance","OK"))) -> Cancelled but Active | R3: =IF(N3="","Missing","Available") -> Available
A4: =TRIM(CLEAN(Raw_Data!A4)) -> MEM0003 | B4: =TRIM(Raw_Data!B4) -> Fatima Das | C4: =_xlfn.XLOOKUP(D4, Branch_Master!A:A, Branch_Master!B:B) -> Mumbai | D4: =TRIM(Raw_Data!D4) -> BR05 | E4: =PROPER(TRIM(Raw_Data!E4)) -> Premium | F4: =IFERROR(DATEVALUE(Raw_Data!F4), Raw_Data!F4) -> 44945 | G4: =IFERROR( IF( IFERROR(DATEVALUE(Raw_Data!G4), Raw_Data!G4) < IFERROR(DATEVALUE(Raw_Data!F4), Raw_Data!F4), IFERROR(DATEVALUE(Raw_Data!F4), Raw_Data!F4) + 30, IFERROR(DATEVALUE(Raw_Data!G4), Raw_Data!G4) ), "" ) -> 45035 | H4: =IFERROR(VALUE(Raw_Data!H4), "") -> 3500 | I4: =IFERROR(VALUE(Raw_Data!I4), "") -> 42000 | J4: =IFERROR( VALUE(SUBSTITUTE(Raw_Data!J4," visits","")), "" ) -> 1 | K4: =IF(TRIM(Raw_Data!K4)="","No",PROPER(TRIM(Raw_Data!K4))) -> No | L4: =PROPER(TRIM(Raw_Data!L4)) -> Weight Loss | M4: Cancelled | N4: =IFERROR(DATEVALUE(Raw_Data!N4), Raw_Data!N4) -> 45257 | P4: =IF(COUNTIF($A$2:A4,A4)>1,"Duplicate","Unique") -> Unique | Q4: =IF(G4<F4,"Expiry Error", IF(AND(M4="Cancelled",N4<>""),"Cancelled but Active", IF(J4>30,"Invalid Attendance","OK"))) -> Cancelled but Active | R4: =IF(N4="","Missing","Available") -> Available
A5: =TRIM(CLEAN(Raw_Data!A5)) -> MEM0004 | B5: =TRIM(Raw_Data!B5) -> Priya D’Souza | C5: =_xlfn.XLOOKUP(D5, Branch_Master!A:A, Branch_Master!B:B) -> Hyderabad | D5: =TRIM(Raw_Data!D5) -> BR04 | E5: =PROPER(TRIM(Raw_Data!E5)) -> Premium | F5: =IFERROR(DATEVALUE(Raw_Data!F5), Raw_Data!F5) -> 45342 | G5: =IFERROR( IF( IFERROR(DATEVALUE(Raw_Data!G5), Raw_Data!G5) < IFERROR(DATEVALUE(Raw_Data!F5), Raw_Data!F5), IFERROR(DATEVALUE(Raw_Data!F5), Raw_Data!F5) + 30, IFERROR(DATEVALUE(Raw_Data!G5), Raw_Data!G5) ), "" ) -> 45432 | H5: =IFERROR(VALUE(Raw_Data!H5), "") -> 3500 | I5: =IFERROR(VALUE(Raw_Data!I5), "") -> 14000 | J5: =IFERROR( VALUE(SUBSTITUTE(Raw_Data!J5," visits","")), "" ) -> 13 | K5: =IF(TRIM(Raw_Data!K5)="","No",PROPER(TRIM(Raw_Data!K5))) -> Yes | L5: =PROPER(TRIM(Raw_Data!L5)) -> Weight Loss | M5: Active | N5: =IFERROR(DATEVALUE(Raw_Data!N5), Raw_Data!N5) -> 45937 | P5: =IF(COUNTIF($A$2:A5,A5)>1,"Duplicate","Unique") -> Unique | Q5: =IF(G5<F5,"Expiry Error", IF(AND(M5="Cancelled",N5<>""),"Cancelled but Active", IF(J5>30,"Invalid Attendance","OK"))) -> OK | R5: =IF(N5="","Missing","Available") -> Available
A6: =TRIM(CLEAN(Raw_Data!A6)) -> MEM0005 | B6: =TRIM(Raw_Data!B6) -> Sanjay Patel | C6: =_xlfn.XLOOKUP(D6, Branch_Master!A:A, Branch_Master!B:B) -> Hyderabad | D6: =TRIM(Raw_Data!D6) -> BR04 | E6: =PROPER(TRIM(Raw_Data!E6)) -> Standard | F6: =IFERROR(DATEVALUE(Raw_Data!F6), Raw_Data!F6) -> 45891 | G6: =IFERROR( IF( IFERROR(DATEVALUE(Raw_Data!G6), Raw_Data!G6) < IFERROR(DATEVALUE(Raw_Data!F6), Raw_Data!F6), IFERROR(DATEVALUE(Raw_Data!F6), Raw_Data!F6) + 30, IFERROR(DATEVALUE(Raw_Data!G6), Raw_Data!G6) ), "" ) -> 46256 | H6: =IFERROR(VALUE(Raw_Data!H6), "") -> 1000 | I6: =IFERROR(VALUE(Raw_Data!I6), "") -> 6000 | J6: =IFERROR( VALUE(SUBSTITUTE(Raw_Data!J6," visits","")), "" ) -> 20 | K6: =IF(TRIM(Raw_Data!K6)="","No",PROPER(TRIM(Raw_Data!K6))) -> No | L6: =PROPER(TRIM(Raw_Data!L6)) -> Weight Loss | M6: Active | N6: =IFERROR(DATEVALUE(Raw_Data!N6), Raw_Data!N6) -> 45960 | P6: =IF(COUNTIF($A$2:A6,A6)>1,"Duplicate","Unique") -> Unique | Q6: =IF(G6<F6,"Expiry Error", IF(AND(M6="Cancelled",N6<>""),"Cancelled but Active", IF(J6>30,"Invalid Attendance","OK"))) -> OK | R6: =IF(N6="","Missing","Available") -> Available
A7: =TRIM(CLEAN(Raw_Data!A7)) -> MEM0006 | B7: =TRIM(Raw_Data!B7) -> Varun Yadav | C7: =_xlfn.XLOOKUP(D7, Branch_Master!A:A, Branch_Master!B:B) -> Chennai | D7: =TRIM(Raw_Data!D7) -> BR03 | E7: =PROPER(TRIM(Raw_Data!E7)) -> Standard | F7: =IFERROR(DATEVALUE(Raw_Data!F7), Raw_Data!F7) -> 45669 | G7: =IFERROR( IF( IFERROR(DATEVALUE(Raw_Data!G7), Raw_Data!G7) < IFERROR(DATEVALUE(Raw_Data!F7), Raw_Data!F7), IFERROR(DATEVALUE(Raw_Data!F7), Raw_Data!F7) + 30, IFERROR(DATEVALUE(Raw_Data!G7), Raw_Data!G7) ), "" ) -> 46034 | H7: =IFERROR(VALUE(Raw_Data!H7), "") -> 3500 | I7: =IFERROR(VALUE(Raw_Data!I7), "") -> 31500 | J7: =IFERROR( VALUE(SUBSTITUTE(Raw_Data!J7," visits","")), "" ) -> 1 | K7: =IF(TRIM(Raw_Data!K7)="","No",PROPER(TRIM(Raw_Data!K7))) -> No | L7: =PROPER(TRIM(Raw_Data!L7)) -> Weight Loss | M7: Cancelled | N7: =IFERROR(DATEVALUE(Raw_Data!N7), Raw_Data!N7) -> 46011 | P7: =IF(COUNTIF($A$2:A7,A7)>1,"Duplicate","Unique") -> Unique | Q7: =IF(G7<F7,"Expiry Error", IF(AND(M7="Cancelled",N7<>""),"Cancelled but Active", IF(J7>30,"Invalid Attendance","OK"))) -> Cancelled but Active | R7: =IF(N7="","Missing","Available") -> Available
A8: =TRIM(CLEAN(Raw_Data!A8)) -> MEM0007 | B8: =TRIM(Raw_Data!B8) -> Zara Joshi | C8: =_xlfn.XLOOKUP(D8, Branch_Master!A:A, Branch_Master!B:B) -> Kochi | D8: =TRIM(Raw_Data!D8) -> BR01 | E8: =PROPER(TRIM(Raw_Data!E8)) -> Standard | F8: =IFERROR(DATEVALUE(Raw_Data!F8), Raw_Data!F8) -> 45116 | G8: =IFERROR( IF( IFERROR(DATEVALUE(Raw_Data!G8), Raw_Data!G8) < IFERROR(DATEVALUE(Raw_Data!F8), Raw_Data!F8), IFERROR(DATEVALUE(Raw_Data!F8), Raw_Data!F8) + 30, IFERROR(DATEVALUE(Raw_Data!G8), Raw_Data!G8) ), "" ) -> 45146 | H8: =IFERROR(VALUE(Raw_Data!H8), "") -> 3500 | I8: =IFERROR(VALUE(Raw_Data!I8), "") -> 17500 | J8: =IFERROR( VALUE(SUBSTITUTE(Raw_Data!J8," visits","")), "" ) -> 7 | K8: =IF(TRIM(Raw_Data!K8)="","No",PROPER(TRIM(Raw_Data!K8))) -> No | L8: =PROPER(TRIM(Raw_Data!L8)) -> Weight Loss | M8: Active | N8: =IFERROR(DATEVALUE(Raw_Data!N8), Raw_Data!N8) -> 45649 | P8: =IF(COUNTIF($A$2:A8,A8)>1,"Duplicate","Unique") -> Unique | Q8: =IF(G8<F8,"Expiry Error", IF(AND(M8="Cancelled",N8<>""),"Cancelled but Active", IF(J8>30,"Invalid Attendance","OK"))) -> OK | R8: =IF(N8="","Missing","Available") -> Available
A9: =TRIM(CLEAN(Raw_Data!A9)) -> MEM0008 | B9: =TRIM(Raw_Data!B9) -> Aditya Khan | C9: =_xlfn.XLOOKUP(D9, Branch_Master!A:A, Branch_Master!B:B) -> Kochi | D9: =TRIM(Raw_Data!D9) -> BR01 | E9: =PROPER(TRIM(Raw_Data!E9)) -> Standard | F9: =IFERROR(DATEVALUE(Raw_Data!F9), Raw_Data!F9) -> 45986 | G9: =IFERROR( IF( IFERROR(DATEVALUE(Raw_Data!G9), Raw_Data!G9) < IFERROR(DATEVALUE(Raw_Data!F9), Raw_Data!F9), IFERROR(DATEVALUE(Raw_Data!F9), Raw_Data!F9) + 30, IFERROR(DATEVALUE(Raw_Data!G9), Raw_Data!G9) ), "" ) -> 46076 | H9: =IFERROR(VALUE(Raw_Data!H9), "") -> 1000 | I9: =IFERROR(VALUE(Raw_Data!I9), "") -> 3000 | J9: =IFERROR( VALUE(SUBSTITUTE(Raw_Data!J9," visits","")), "" ) -> 8 | K9: =IF(TRIM(Raw_Data!K9)="","No",PROPER(TRIM(Raw_Data!K9))) -> No | L9: =PROPER(TRIM(Raw_Data!L9)) -> Muscle Gain | M9: Active | N9: =IFERROR(DATEVALUE(Raw_Data!N9), Raw_Data!N9) -> 46071 | P9: =IF(COUNTIF($A$2:A9,A9)>1,"Duplicate","Unique") -> Unique | Q9: =IF(G9<F9,"Expiry Error", IF(AND(M9="Cancelled",N9<>""),"Cancelled but Active", IF(J9>30,"Invalid Attendance","OK"))) -> OK | R9: =IF(N9="","Missing","Available") -> Available
A10: =TRIM(CLEAN(Raw_Data!A10)) -> MEM0009 | B10: =TRIM(Raw_Data!B10) -> Lakshmi Shetty | C10: =_xlfn.XLOOKUP(D10, Branch_Master!A:A, Branch_Master!B:B) -> Trivandrum | D10: =TRIM(Raw_Data!D10) -> BR06 | E10: =PROPER(TRIM(Raw_Data!E10)) -> Premium | F10: =IFERROR(DATEVALUE(Raw_Data!F10), Raw_Data!F10) -> 45552 | G10: =IFERROR( IF( IFERROR(DATEVALUE(Raw_Data!G10), Raw_Data!G10) < IFERROR(DATEVALUE(Raw_Data!F10), Raw_Data!F10), IFERROR(DATEVALUE(Raw_Data!F10), Raw_Data!F10) + 30, IFERROR(DATEVALUE(Raw_Data!G10), Raw_Data!G10) ), "" ) -> 45582 | H10: =IFERROR(VALUE(Raw_Data!H10), "") -> 2000 | I10: =IFERROR(VALUE(Raw_Data!I10), "") -> 4000 | J10: =IFERROR( VALUE(SUBSTITUTE(Raw_Data!J10," visits","")), "" ) -> 14 | K10: =IF(TRIM(Raw_Data!K10)="","No",PROPER(TRIM(Raw_Data!K10))) -> Yes | L10: =PROPER(TRIM(Raw_Data!L10)) -> General Fitness | M10: Active | N10: =IFERROR(DATEVALUE(Raw_Data!N10), Raw_Data!N10) -> 45846 | P10: =IF(COUNTIF($A$2:A10,A10)>1,"Duplicate","Unique") -> Unique | Q10: =IF(G10<F10,"Expiry Error", IF(AND(M10="Cancelled",N10<>""),"Cancelled but Active", IF(J10>30,"Invalid Attendance","OK"))) -> OK | R10: =IF(N10="","Missing","Available") -> Available
A11: =TRIM(CLEAN(Raw_Data!A11)) -> MEM0010 | B11: =TRIM(Raw_Data!B11) -> Pooja Iyer | C11: =_xlfn.XLOOKUP(D11, Branch_Master!A:A, Branch_Master!B:B) -> Chennai | D11: =TRIM(Raw_Data!D11) -> BR03 | E11: =PROPER(TRIM(Raw_Data!E11)) -> Basic | F11: =IFERROR(DATEVALUE(Raw_Data!F11), Raw_Data!F11) -> 45390 | G11: =IFERROR( IF( IFERROR(DATEVALUE(Raw_Data!G11), Raw_Data!G11) < IFERROR(DATEVALUE(Raw_Data!F11), Raw_Data!F11), IFERROR(DATEVALUE(Raw_Data!F11), Raw_Data!F11) + 30, IFERROR(DATEVALUE(Raw_Data!G11), Raw_Data!G11) ), "" ) -> 45420 | H11: =IFERROR(VALUE(Raw_Data!H11), "") -> 3500 | I11: =IFERROR(VALUE(Raw_Data!I11), "") -> 24500 | J11: =IFERROR( VALUE(SUBSTITUTE(Raw_Data!J11," visits","")), "" ) -> 15 | K11: =IF(TRIM(Raw_Data!K11)="","No",PROPER(TRIM(Raw_Data!K11))) -> Yes | L11: =PROPER(TRIM(Raw_Data!L11)) -> Muscle Gain | M11: Active | N11: =IFERROR(DATEVALUE(Raw_Data!N11), Raw_Data!N11) -> 45926 | P11: =IF(COUNTIF($A$2:A11,A11)>1,"Duplicate","Unique") -> Unique | Q11: =IF(G11<F11,"Expiry Error", IF(AND(M11="Cancelled",N11<>""),"Cancelled but Active", IF(J11>30,"Invalid Attendance","OK"))) -> OK | R11: =IF(N11="","Missing","Available") -> Available
A12: =TRIM(CLEAN(Raw_Data!A12)) -> MEM0011 | B12: =TRIM(Raw_Data!B12) -> Siddharth Shaikh | C12: =_xlfn.XLOOKUP(D12, Branch_Master!A:A, Branch_Master!B:B) -> Kochi | D12: =TRIM(Raw_Data!D12) -> BR01 | E12: =PROPER(TRIM(Raw_Data!E12)) -> Standard | F12: =IFERROR(DATEVALUE(Raw_Data!F12), Raw_Data!F12) -> 45093 | G12: =IFERROR( IF( IFERROR(DATEVALUE(Raw_Data!G12), Raw_Data!G12) < IFERROR(DATEVALUE(Raw_Data!F12), Raw_Data!F12), IFERROR(DATEVALUE(Raw_Data!F12), Raw_Data!F12) + 30, IFERROR(DATEVALUE(Raw_Data!G12), Raw_Data!G12) ), "" ) -> 45458 | H12: =IFERROR(VALUE(Raw_Data!H12), "") -> 2000 | I12: =IFERROR(VALUE(Raw_Data!I12), "") -> 2000 | J12: =IFERROR( VALUE(SUBSTITUTE(Raw_Data!J12," visits","")), "" ) -> 23 | K12: =IF(TRIM(Raw_Data!K12)="","No",PROPER(TRIM(Raw_Data!K12))) -> Yes | L12: =PROPER(TRIM(Raw_Data!L12)) -> General Fitness | M12: Active | N12: =IFERROR(DATEVALUE(Raw_Data!N12), Raw_Data!N12) -> 45535 | P12: =IF(COUNTIF($A$2:A12,A12)>1,"Duplicate","Unique") -> Unique | Q12: =IF(G12<F12,"Expiry Error", IF(AND(M12="Cancelled",N12<>""),"Cancelled but Active", IF(J12>30,"Invalid Attendance","OK"))) -> OK | R12: =IF(N12="","Missing","Available") -> Available
A13: =TRIM(CLEAN(Raw_Data!A13)) -> MEM0012 | B13: =TRIM(Raw_Data!B13) -> Ishita Nambiar | C13: =_xlfn.XLOOKUP(D13, Branch_Master!A:A, Branch_Master!B:B) -> Trivandrum | D13: =TRIM(Raw_Data!D13) -> BR06 | E13: =PROPER(TRIM(Raw_Data!E13)) -> Basic | F13: =IFERROR(DATEVALUE(Raw_Data!F13), Raw_Data!F13) -> 45363 | G13: =IFERROR( IF( IFERROR(DATEVALUE(Raw_Data!G13), Raw_Data!G13) < IFERROR(DATEVALUE(Raw_Data!F13), Raw_Data!F13), IFERROR(DATEVALUE(Raw_Data!F13), Raw_Data!F13) + 30, IFERROR(DATEVALUE(Raw_Data!G13), Raw_Data!G13) ), "" ) -> 45728 | H13: =IFERROR(VALUE(Raw_Data!H13), "") -> 2000 | I13: =IFERROR(VALUE(Raw_Data!I13), "") -> 24000 | J13: =IFERROR( VALUE(SUBSTITUTE(Raw_Data!J13," visits","")), "" ) -> 14 | K13: =IF(TRIM(Raw_Data!K13)="","No",PROPER(TRIM(Raw_Data!K13))) -> Yes | L13: =PROPER(TRIM(Raw_Data!L13)) -> Weight Loss | M13: Active | N13: =IFERROR(DATEVALUE(Raw_Data!N13), Raw_Data!N13) -> 46031 | P13: =IF(COUNTIF($A$2:A13,A13)>1,"Duplicate","Unique") -> Unique | Q13: =IF(G13<F13,"Expiry Error", IF(AND(M13="Cancelled",N13<>""),"Cancelled but Active", IF(J13>30,"Invalid Attendance","OK"))) -> OK | R13: =IF(N13="","Missing","Available") -> Available
... A801: =TRIM(CLEAN(Raw_Data!A801)) -> MEM0800 | B801: =TRIM(Raw_Data!B801) -> Ayesha Agarwal | C801: =_xlfn.XLOOKUP(D801, Branch_Master!A:A, Branch_Master!B:B) -> Kochi | D801: =TRIM(Raw_Data!D801) -> BR01 | E801: =PROPER(TRIM(Raw_Data!E801)) -> Standard | F801: =IFERROR(DATEVALUE(Raw_Data!F801), Raw_Data!F801) -> 45975 | G801: =IFERROR( IF( IFERROR(DATEVALUE(Raw_Data!G801), Raw_Data!G801) < IFERROR(DATEVALUE(Raw_Data!F801), Raw_Data!F801), IFERROR(DATEVALUE(Raw_Data!F801), Raw_Data!F801) + 30, IFERROR(DATEVALUE(Raw_Data!G801), Raw_Data!G801) ), "" ) -> 46065 | H801: =IFERROR(VALUE(Raw_Data!H801), "") -> 3500 | I801: =IFERROR(VALUE(Raw_Data!I801), "") -> 35000 | J801: =IFERROR( VALUE(SUBSTITUTE(Raw_Data!J801," visits","")), "" ) -> 4 | K801: =IF(TRIM(Raw_Data!K801)="","No",PROPER(TRIM(Raw_Data!K801))) -> No | L801: =PROPER(TRIM(Raw_Data!L801)) -> Muscle Gain | M801: Cancelled | N801: =IFERROR(DATEVALUE(Raw_Data!N801), Raw_Data!N801) -> 46096 | P801: =IF(COUNTIF($A$2:A801,A801)>1,"Duplicate","Unique") -> Unique | Q801: =IF(G801<F801,"Expiry Error", IF(AND(M801="Cancelled",N801<>""),"Cancelled but Active", IF(J801>30,"Invalid Attendance","OK"))) -> Cancelled but Active | R801: =IF(N801="","Missing","Available") -> Available
A802: =TRIM(CLEAN(Raw_Data!A802)) -> MEM0801 | B802: =TRIM(CLEAN(Raw_Data!B802)) -> Sanjay Lewis | C802: =_xlfn.XLOOKUP(D802, Branch_Master!A:A, Branch_Master!B:B) -> Hyderabad | D802: =TRIM(CLEAN(Raw_Data!D802)) -> BR04 | E802: =PROPER(TRIM(Raw_Data!E802)) -> Premium | F802: =IFERROR(DATEVALUE(Raw_Data!F802), Raw_Data!F802) -> 45630 | G802: =IFERROR( IF( IFERROR(DATEVALUE(Raw_Data!G802), Raw_Data!G802) < IFERROR(DATEVALUE(Raw_Data!F802), Raw_Data!F802), IFERROR(DATEVALUE(Raw_Data!F802), Raw_Data!F802) + 30, IFERROR(DATEVALUE(Raw_Data!G802), Raw_Data!G802) ), "" ) -> 45995 | H802: =IFERROR(VALUE(Raw_Data!H802), "") -> 1000 | I802: =IFERROR(VALUE(Raw_Data!I802), "") -> 5000 | J802: =IFERROR( VALUE(SUBSTITUTE(Raw_Data!J802," visits","")), "" ) | K802: =TRIM(CLEAN(Raw_Data!K802)) -> Yes | L802: =TRIM(CLEAN(Raw_Data!L802)) -> General Fitness | M802: =TRIM(CLEAN(Raw_Data!M802)) -> Cancelled | N802: =TRIM(CLEAN(Raw_Data!N802)) -> 46022 | P802: =IF(COUNTIF($A$2:A802,A802)>1,"Duplicate","Unique") -> Unique | Q802: =IF(G802<F802,"Expiry Error", IF(AND(M802="Cancelled",N802<>""),"Cancelled but Active", IF(J802>30,"Invalid Attendance","OK"))) -> Cancelled but Active | R802: =IF(N802="","Missing","Available") -> Available
A803: =TRIM(CLEAN(Raw_Data!A803)) -> MEM0802 | B803: =TRIM(CLEAN(Raw_Data!B803)) -> Lakshmi Iyer | C803: =_xlfn.XLOOKUP(D803, Branch_Master!A:A, Branch_Master!B:B) -> Chennai | D803: =TRIM(CLEAN(Raw_Data!D803)) -> BR03 | E803: =PROPER(TRIM(Raw_Data!E803)) -> Standard | F803: =IFERROR(DATEVALUE(Raw_Data!F803), Raw_Data!F803) -> 45794 | G803: =IFERROR( IF( IFERROR(DATEVALUE(Raw_Data!G803), Raw_Data!G803) < IFERROR(DATEVALUE(Raw_Data!F803), Raw_Data!F803), IFERROR(DATEVALUE(Raw_Data!F803), Raw_Data!F803) + 30, IFERROR(DATEVALUE(Raw_Data!G803), Raw_Data!G803) ), "" ) -> 45824 | H803: =IFERROR(VALUE(Raw_Data!H803), "") -> 3500 | I803: =IFERROR(VALUE(Raw_Data!I803), "") -> 38500 | J803: =IFERROR( VALUE(SUBSTITUTE(Raw_Data!J803," visits","")), "" ) | K803: =TRIM(CLEAN(Raw_Data!K803)) -> No | L803: =TRIM(CLEAN(Raw_Data!L803)) -> Muscle Gain | M803: =TRIM(CLEAN(Raw_Data!M803)) -> Cancelled | N803: =TRIM(CLEAN(Raw_Data!N803)) -> 46050 | P803: =IF(COUNTIF($A$2:A803,A803)>1,"Duplicate","Unique") -> Unique | Q803: =IF(G803<F803,"Expiry Error", IF(AND(M803="Cancelled",N803<>""),"Cancelled but Active", IF(J803>30,"Invalid Attendance","OK"))) -> Cancelled but Active | R803: =IF(N803="","Missing","Available") -> Available
